Workbook

Sheet 사용법
B2: 주식 매매일지 · 사용법
B4: ■ 시트 구성
B5: 사용법 | C5: 이 시트. 입력 규칙과 색 규칙 설명.
B6: 설정 | C6: 전략명·초기자본·수수료율·대시보드 시작월 등 공통 파라미터. 노란 칸만 고치면 됨.
B7: 거래장부_<전략> | C7: 매매 1건(매수~매도 한 사이클)이 1행. 실제로 입력하는 곳.
B8: 대시보드_<전략> | C8: 해당 전략의 성과 요약. 전부 수식이므로 직접 고치지 말 것.
B9: 원본거래내역 | C9: 증권사 HTS/MTS에서 뽑은 거래내역 원본을 그대로 붙여넣는 보관용 시트.
B11: ■ 색 규칙
B12: 노란 배경 / 파란 글씨 | C12: 직접 입력하는 칸.
B13: 회색 배경 / 검은 글씨 | C13: 자동 계산되는 칸. 덮어쓰면 수식이 깨짐.
B14: 초록 글씨 | C14: 다른 시트를 참조하는 값.
B15: 주황 배경 | C15: 예시 행. 실제 사용 전에 삭제할 것.
B17: ■ 입력 순서
B18: 1 | C18: 매수 체결 직후: 종목코드·종목명·매수일자·매수단가·수량·매수수수료·매매유형·메모를 입력한다.
B19: 2 | C19: 이 시점에는 매도 관련 칸이 비어 있으므로 상태가 '보유중'으로 잡히고, 손익 계산에서 제외된다.
B20: 3 | C20: 매도 체결 후: 매도일자·매도단가·매도수수료·제세금을 채운다. 상태가 '청산'으로 바뀌며 손익·수익률·보유일수가 계산된다.
B21: 4 | C21: 분할매수/분할매도는 평균단가와 총수량으로 합쳐 한 행에 적거나, 매수 묶음별로 행을 나눠 적는다(둘 중 하나로 일관되게).
B22: 5 | C22: 대시보드는 파일을 열 때 자동 재계산된다. 값이 안 바뀌면 F9(수동 계산 모드일 때)를 누른다.
B24: ■ 지표 정의
B25: 순손익 | C25: 총매도금액 − 총매수금액 − 총비용(매수수수료+매도수수료+제세금). 세후·수수료후 실현손익.
B26: 수익률 | C26: 순손익 ÷ 총매수금액. 투입원금 대비 실현 수익률이며 보유기간으로 연환산하지 않은 값.
B27: 승률 | C27: 수익 거래 수 ÷ 청산 거래 수. 보유중 거래는 분모·분자 모두에서 제외.
B28: 손익비(Profit Factor) | C28: 총수익 합계 ÷ |총손실 합계|. 1보다 크면 전략이 플러스.
B29: 평균 손익비(R/R) | C29: 평균 수익 ÷ |평균 손실|. 한 번 이길 때 버는 돈이 한 번 질 때 잃는 돈의 몇 배인지.
B30: 기대값 | C30: 총 실현손익 ÷ 청산 거래 수. 거래 1건당 평균적으로 기대되는 금액.
B31: 보유일수 | C31: 청산 거래는 매도일자−매수일자. 보유중 거래는 오늘−매수일자(파일 열 때마다 갱신).
B32: 최대 연속 수익/손실 | C32: 장부의 행 순서 기준. 매수일자 오름차순으로 정렬해 두어야 의미가 맞음.
B34: ■ 전략 추가 방법
B35: 코드로 추가 | C35: trading_journal/build_journal.py 의 STRATEGIES 리스트에 전략명을 추가하고 다시 실행하면 시트 쌍이 생성된다.
B36: 엑셀에서 추가 | C36: 거래장부/대시보드 시트를 각각 우클릭 → 이동/복사 → 복사본 만들기 후 이름을 바꾸고, 대시보드 수식의 시트 이름을 새 장부 이름으로 일괄 치환한다.
B37: 주의 | C37: 전략을 나누는 기준은 보유기간이 아니라 '매매 근거'다. 같은 종목이라도 근거가 다르면 다른 장부에 기록해야 통계가 섞이지 않는다.

Sheet 설정
B2: 공통 설정
B4: 항목 | C4: 값 | D4: 설명
B5: 계좌명 | C5: 하나증권 / 안현준 | D5: 여러 계좌를 쓰면 계좌별로 파일을 나누는 편이 낫다.
B6: 기준 통화 | C6: KRW | D6: 원화 기준. 해외주식은 별도 파일 권장.
B7: 초기 투자원금 | C7: 4000000 | D7: 원본거래내역의 입금 합계. 계좌 전체 수익률 계산의 기준.
B8: 대시보드 시작월 | C8: 45931 | D8: 월별 성과 표의 첫 달. 여기서부터 24개월이 표시된다.
B9: 매수 수수료율 | C9: 0.00015 | D9: 참고값. 장부에는 실제 체결 수수료를 원 단위로 직접 입력한다.
B10: 매도 수수료율 | C10: 0.00015 | D10: 참고값.
B11: 증권거래세율 | C11: 0.0018 | D11: 2025년 코스피/코스닥 기준 참고값. 실제 부과액을 장부에 입력한다.
B12: 1거래 최대 손실 한도 | C12: 0.02 | D12: 총자본 대비 손절 한도. 리스크 관리 기준선(수식에는 쓰이지 않음).
B14: 전략 목록
B15: 전략명 | C15: 장부 시트 | D15: 설명
B16: 스윙트레이딩 | C16: 거래장부_스윙트레이딩 | D16: 수일~수주 보유. 추세/수급 기반 진입, 목표가·손절가 사전 설정.
B18: 매매유형 선택지
B19: 목록 | C19: 돌파, 눌림목, 추세추종, 실적, 배당, 테마, 분할매수, 역추세, 기타 | D19: 거래장부의 '매매유형' 열 드롭다운 값. 바꾸려면 각 장부 시트의 데이터 유효성 목록도 함께 수정.
B21: ※ 수수료율·거래세율은 참고용 상수이며 손익 계산에 직접 쓰이지 않는다. 장부에는 증권사가 실제로 부과한 금액을 원 단위로 입력할 것.

Sheet 거래장부_스윙트레이딩
A1: 스윙트레이딩 거래장부
A2: 전략 | B2: 스윙트레이딩 | D2: 청산 건수 | E2: =COUNTIF($L$6:$L$505,"청산") -> 2 | F2: 보유중 | G2: =COUNTIF($L$6:$L$505,"보유중") -> 1 | H2: 실현손익 합계 | I2: =SUM($P$6:$P$505) -> 90911
A3: 입력: 노란 칸(파란 글씨)만 채운다. · 자동: 회색 칸은 수식이므로 덮어쓰지 말 것. · 매수 직후엔 매수 칸만 채우고(상태=보유중), 매도 후 매도 칸을 채우면 상태가 '청산'으로 바뀌며 손익이 계산된다. · 주황색 예시 3행은 삭제 후 사용.
A5: No | B5: 종목코드 | C5: 종목명 | D5: 매수일자 | E5: 매수단가 | F5: 수량 | G5: 매수 수수료 | H5: 매도일자 | I5: 매도단가 | J5: 매도 수수료 | K5: 제세금 | L5: 상태 | M5: 총매수금액 | N5: 총매도금액 | O5: 총비용 | P5: 순손익 | Q5: 수익률 | R5: 보유일수 | S5: 청산월 | T5: 매매유형 | U5: 메모 / 매매근거 | V5: 연속승 (보조) | W5: 연속패 (보조)
A6: =IF($B6="","",ROW()-5) -> 1 | B6: 005930 | C6: 삼성전자 | D6: 45950 | E6: 68000 | F6: 30 | G6: 306 | H6: 45975 | I6: 74500 | J6: 335 | K6: 4023 | L6: =IF($B6="","",IF($H6="","보유중","청산")) -> 청산 | M6: =IF($B6="","",$E6*$F6) -> 2040000 | N6: =IF($L6="청산",$I6*$F6,"") -> 2235000 | O6: =IF($B6="","",$G6+$J6+$K6) -> 4664 | P6: =IF($L6="청산",$N6-$M6-$O6,"") -> 190336 | Q6: =IF($L6="청산",IF($M6=0,"",$P6/$M6),"") -> 0.093301961 | R6: =IF($B6="","",IF($L6="청산",$H6-$D6,IF($D6="","",TODAY()-$D6))) -> 25 | S6: =IF($L6="청산",DATE(YEAR($H6),MONTH($H6),1),"") -> 45962 | T6: 돌파 | U6: 예시) 전고점 돌파 + 거래대금 급증. 목표 75,000 / 손절 64,500 | V6: =IF($B6="","",IF($L6<>"청산",N(V5),IF($P6>0,N(V5)+1,0))) -> 1 | W6: =IF($B6="","",IF($L6<>"청산",N(W5),IF($P6<0,N(W5)+1,0))) -> 0
A7: =IF($B7="","",ROW()-5) -> 2 | B7: 035420 | C7: NAVER | D7: 45964 | E7: 215000 | F7: 8 | G7: 258 | H7: 45971 | I7: 203000 | J7: 243 | K7: 2924 | L7: =IF($B7="","",IF($H7="","보유중","청산")) -> 청산 | M7: =IF($B7="","",$E7*$F7) -> 1720000 | N7: =IF($L7="청산",$I7*$F7,"") -> 1624000 | O7: =IF($B7="","",$G7+$J7+$K7) -> 3425 | P7: =IF($L7="청산",$N7-$M7-$O7,"") -> -99425 | Q7: =IF($L7="청산",IF($M7=0,"",$P7/$M7),"") -> -0.057805233 | R7: =IF($B7="","",IF($L7="청산",$H7-$D7,IF($D7="","",TODAY()-$D7))) -> 7 | S7: =IF($L7="청산",DATE(YEAR($H7),MONTH($H7),1),"") -> 45962 | T7: 눌림목 | U7: 예시) 20일선 지지 실패로 손절. 진입 근거 조기 소멸 | V7: =IF($B7="","",IF($L7<>"청산",N(V6),IF($P7>0,N(V6)+1,0))) -> 0 | W7: =IF($B7="","",IF($L7<>"청산",N(W6),IF($P7<0,N(W6)+1,0))) -> 1
A8: =IF($B8="","",ROW()-5) -> 3 | B8: 000660 | C8: SK하이닉스 | D8: 45992 | E8: 178000 | F8: 10 | G8: 267 | L8: =IF($B8="","",IF($H8="","보유중","청산")) -> 보유중 | M8: =IF($B8="","",$E8*$F8) -> 1780000 | N8: =IF($L8="청산",$I8*$F8,"") | O8: =IF($B8="","",$G8+$J8+$K8) -> 267 | P8: =IF($L8="청산",$N8-$M8-$O8,"") | Q8: =IF($L8="청산",IF($M8=0,"",$P8/$M8),"") | R8: =IF($B8="","",IF($L8="청산",$H8-$D8,IF($D8="","",TODAY()-$D8))) -> 275 | S8: =IF($L8="청산",DATE(YEAR($H8),MONTH($H8),1),"") | T8: 추세추종 | U8: 예시) 보유중 행. 매도 칸이 비면 손익 계산에서 제외됨 | V8: =IF($B8="","",IF($L8<>"청산",N(V7),IF($P8>0,N(V7)+1,0))) -> 0 | W8: =IF($B8="","",IF($L8<>"청산",N(W7),IF($P8<0,N(W7)+1,0))) -> 1
A9: =IF($B9="","",ROW()-5) | L9: =IF($B9="","",IF($H9="","보유중","청산")) | M9: =IF($B9="","",$E9*$F9) | N9: =IF($L9="청산",$I9*$F9,"") | O9: =IF($B9="","",$G9+$J9+$K9) | P9: =IF($L9="청산",$N9-$M9-$O9,"") | Q9: =IF($L9="청산",IF($M9=0,"",$P9/$M9),"") | R9: =IF($B9="","",IF($L9="청산",$H9-$D9,IF($D9="","",TODAY()-$D9))) | S9: =IF($L9="청산",DATE(YEAR($H9),MONTH($H9),1),"") | V9: =IF($B9="","",IF($L9<>"청산",N(V8),IF($P9>0,N(V8)+1,0))) | W9: =IF($B9="","",IF($L9<>"청산",N(W8),IF($P9<0,N(W8)+1,0)))
A10: =IF($B10="","",ROW()-5) | L10: =IF($B10="","",IF($H10="","보유중","청산")) | M10: =IF($B10="","",$E10*$F10) | N10: =IF($L10="청산",$I10*$F10,"") | O10: =IF($B10="","",$G10+$J10+$K10) | P10: =IF($L10="청산",$N10-$M10-$O10,"") | Q10: =IF($L10="청산",IF($M10=0,"",$P10/$M10),"") | R10: =IF($B10="","",IF($L10="청산",$H10-$D10,IF($D10="","",TODAY()-$D10))) | S10: =IF($L10="청산",DATE(YEAR($H10),MONTH($H10),1),"") | V10: =IF($B10="","",IF($L10<>"청산",N(V9),IF($P10>0,N(V9)+1,0))) | W10: =IF($B10="","",IF($L10<>"청산",N(W9),IF($P10<0,N(W9)+1,0)))
A11: =IF($B11="","",ROW()-5) | L11: =IF($B11="","",IF($H11="","보유중","청산")) | M11: =IF($B11="","",$E11*$F11) | N11: =IF($L11="청산",$I11*$F11,"") | O11: =IF($B11="","",$G11+$J11+$K11) | P11: =IF($L11="청산",$N11-$M11-$O11,"") | Q11: =IF($L11="청산",IF($M11=0,"",$P11/$M11),"") | R11: =IF($B11="","",IF($L11="청산",$H11-$D11,IF($D11="","",TODAY()-$D11))) | S11: =IF($L11="청산",DATE(YEAR($H11),MONTH($H11),1),"") | V11: =IF($B11="","",IF($L11<>"청산",N(V10),IF($P11>0,N(V10)+1,0))) | W11: =IF($B11="","",IF($L11<>"청산",N(W10),IF($P11<0,N(W10)+1,0)))
A12: =IF($B12="","",ROW()-5) | L12: =IF($B12="","",IF($H12="","보유중","청산")) | M12: =IF($B12="","",$E12*$F12) | N12: =IF($L12="청산",$I12*$F12,"") | O12: =IF($B12="","",$G12+$J12+$K12) | P12: =IF($L12="청산",$N12-$M12-$O12,"") | Q12: =IF($L12="청산",IF($M12=0,"",$P12/$M12),"") | R12: =IF($B12="","",IF($L12="청산",$H12-$D12,IF($D12="","",TODAY()-$D12))) | S12: =IF($L12="청산",DATE(YEAR($H12),MONTH($H12),1),"") | V12: =IF($B12="","",IF($L12<>"청산",N(V11),IF($P12>0,N(V11)+1,0))) | W12: =IF($B12="","",IF($L12<>"청산",N(W11),IF($P12<0,N(W11)+1,0)))
A13: =IF($B13="","",ROW()-5) | L13: =IF($B13="","",IF($H13="","보유중","청산")) | M13: =IF($B13="","",$E13*$F13) | N13: =IF($L13="청산",$I13*$F13,"") | O13: =IF($B13="","",$G13+$J13+$K13) | P13: =IF($L13="청산",$N13-$M13-$O13,"") | Q13: =IF($L13="청산",IF($M13=0,"",$P13/$M13),"") | R13: =IF($B13="","",IF($L13="청산",$H13-$D13,IF($D13="","",TODAY()-$D13))) | S13: =IF($L13="청산",DATE(YEAR($H13),MONTH($H13),1),"") | V13: =IF($B13="","",IF($L13<>"청산",N(V12),IF($P13>0,N(V12)+1,0))) | W13: =IF($B13="","",IF($L13<>"청산",N(W12),IF($P13<0,N(W12)+1,0)))
A14: =IF($B14="","",ROW()-5) | L14: =IF($B14="","",IF($H14="","보유중","청산")) | M14: =IF($B14="","",$E14*$F14) | N14: =IF($L14="청산",$I14*$F14,"") | O14: =IF($B14="","",$G14+$J14+$K14) | P14: =IF($L14="청산",$N14-$M14-$O14,"") | Q14: =IF($L14="청산",IF($M14=0,"",$P14/$M14),"") | R14: =IF($B14="","",IF($L14="청산",$H14-$D14,IF($D14="","",TODAY()-$D14))) | S14: =IF($L14="청산",DATE(YEAR($H14),MONTH($H14),1),"") | V14: =IF($B14="","",IF($L14<>"청산",N(V13),IF($P14>0,N(V13)+1,0))) | W14: =IF($B14="","",IF($L14<>"청산",N(W13),IF($P14<0,N(W13)+1,0)))
A15: =IF($B15="","",ROW()-5) | L15: =IF($B15="","",IF($H15="","보유중","청산")) | M15: =IF($B15="","",$E15*$F15) | N15: =IF($L15="청산",$I15*$F15,"") | O15: =IF($B15="","",$G15+$J15+$K15) | P15: =IF($L15="청산",$N15-$M15-$O15,"") | Q15: =IF($L15="청산",IF($M15=0,"",$P15/$M15),"") | R15: =IF($B15="","",IF($L15="청산",$H15-$D15,IF($D15="","",TODAY()-$D15))) | S15: =IF($L15="청산",DATE(YEAR($H15),MONTH($H15),1),"") | V15: =IF($B15="","",IF($L15<>"청산",N(V14),IF($P15>0,N(V14)+1,0))) | W15: =IF($B15="","",IF($L15<>"청산",N(W14),IF($P15<0,N(W14)+1,0)))
A16: =IF($B16="","",ROW()-5) | L16: =IF($B16="","",IF($H16="","보유중","청산")) | M16: =IF($B16="","",$E16*$F16) | N16: =IF($L16="청산",$I16*$F16,"") | O16: =IF($B16="","",$G16+$J16+$K16) | P16: =IF($L16="청산",$N16-$M16-$O16,"") | Q16: =IF($L16="청산",IF($M16=0,"",$P16/$M16),"") | R16: =IF($B16="","",IF($L16="청산",$H16-$D16,IF($D16="","",TODAY()-$D16))) | S16: =IF($L16="청산",DATE(YEAR($H16),MONTH($H16),1),"") | V16: =IF($B16="","",IF($L16<>"청산",N(V15),IF($P16>0,N(V15)+1,0))) | W16: =IF($B16="","",IF($L16<>"청산",N(W15),IF($P16<0,N(W15)+1,0)))
A17: =IF($B17="","",ROW()-5) | L17: =IF($B17="","",IF($H17="","보유중","청산")) | M17: =IF($B17="","",$E17*$F17) | N17: =IF($L17="청산",$I17*$F17,"") | O17: =IF($B17="","",$G17+$J17+$K17) | P17: =IF($L17="청산",$N17-$M17-$O17,"") | Q17: =IF($L17="청산",IF($M17=0,"",$P17/$M17),"") | R17: =IF($B17="","",IF($L17="청산",$H17-$D17,IF($D17="","",TODAY()-$D17))) | S17: =IF($L17="청산",DATE(YEAR($H17),MONTH($H17),1),"") | V17: =IF($B17="","",IF($L17<>"청산",N(V16),IF($P17>0,N(V16)+1,0))) | W17: =IF($B17="","",IF($L17<>"청산",N(W16),IF($P17<0,N(W16)+1,0)))
A18: =IF($B18="","",ROW()-5) | L18: =IF($B18="","",IF($H18="","보유중","청산")) | M18: =IF($B18="","",$E18*$F18) | N18: =IF($L18="청산",$I18*$F18,"") | O18: =IF($B18="","",$G18+$J18+$K18) | P18: =IF($L18="청산",$N18-$M18-$O18,"") | Q18: =IF($L18="청산",IF($M18=0,"",$P18/$M18),"") | R18: =IF($B18="","",IF($L18="청산",$H18-$D18,IF($D18="","",TODAY()-$D18))) | S18: =IF($L18="청산",DATE(YEAR($H18),MONTH($H18),1),"") | V18: =IF($B18="","",IF($L18<>"청산",N(V17),IF($P18>0,N(V17)+1,0))) | W18: =IF($B18="","",IF($L18<>"청산",N(W17),IF($P18<0,N(W17)+1,0)))
A19: =IF($B19="","",ROW()-5) | L19: =IF($B19="","",IF($H19="","보유중","청산")) | M19: =IF($B19="","",$E19*$F19) | N19: =IF($L19="청산",$I19*$F19,"") | O19: =IF($B19="","",$G19+$J19+$K19) | P19: =IF($L19="청산",$N19-$M19-$O19,"") | Q19: =IF($L19="청산",IF($M19=0,"",$P19/$M19),"") | R19: =IF($B19="","",IF($L19="청산",$H19-$D19,IF($D19="","",TODAY()-$D19))) | S19: =IF($L19="청산",DATE(YEAR($H19),MONTH($H19),1),"") | V19: =IF($B19="","",IF($L19<>"청산",N(V18),IF($P19>0,N(V18)+1,0))) | W19: =IF($B19="","",IF($L19<>"청산",N(W18),IF($P19<0,N(W18)+1,0)))
A20: =IF($B20="","",ROW()-5) | L20: =IF($B20="","",IF($H20="","보유중","청산")) | M20: =IF($B20="","",$E20*$F20) | N20: =IF($L20="청산",$I20*$F20,"") | O20: =IF($B20="","",$G20+$J20+$K20) | P20: =IF($L20="청산",$N20-$M20-$O20,"") | Q20: =IF($L20="청산",IF($M20=0,"",$P20/$M20),"") | R20: =IF($B20="","",IF($L20="청산",$H20-$D20,IF($D20="","",TODAY()-$D20))) | S20: =IF($L20="청산",DATE(YEAR($H20),MONTH($H20),1),"") | V20: =IF($B20="","",IF($L20<>"청산",N(V19),IF($P20>0,N(V19)+1,0))) | W20: =IF($B20="","",IF($L20<>"청산",N(W19),IF($P20<0,N(W19)+1,0)))
... A505: =IF($B505="","",ROW()-5) | L505: =IF($B505="","",IF($H505="","보유중","청산")) | M505: =IF($B505="","",$E505*$F505) | N505: =IF($L505="청산",$I505*$F505,"") | O505: =IF($B505="","",$G505+$J505+$K505) | P505: =IF($L505="청산",$N505-$M505-$O505,"") | Q505: =IF($L505="청산",IF($M505=0,"",$P505/$M505),"") | R505: =IF($B505="","",IF($L505="청산",$H505-$D505,IF($D505="","",TODAY()-$D505))) | S505: =IF($L505="청산",DATE(YEAR($H505),MONTH($H505),1),"") | V505: =IF($B505="","",IF($L505<>"청산",N(V504),IF($P505>0,N(V504)+1,0))) | W505: =IF($B505="","",IF($L505<>"청산",N(W504),IF($P505<0,N(W504)+1,0)))
C506: 합계 / 평균 | M506: =SUM(M$6:M$505) -> 5540000 | N506: =SUM(N$6:N$505) -> 3859000 | O506: =SUM(O$6:O$505) -> 8356 | P506: =SUM(P$6:P$505) -> 90911 | Q506: =IFERROR(P506/SUMIF($L$6:$L$505,"청산",$M$6:$M$505),"") -> 0.024178457 | R506: =IFERROR(AVERAGEIFS($R$6:$R$505,$L$6:$L$505,"청산"),"") -> 16

Sheet 대시보드_스윙트레이딩
B2: 스윙트레이딩 성과 대시보드
B3: 기준일 | C3: =TODAY() -> 46267 | E3: 장부 시트: 거래장부_스윙트레이딩 · 모든 값은 수식으로 자동 계산됨 (직접 수정 금지)
B5: 종합 성과 | E5: 평균 지표 | H5: 최고 / 최악
B6: 청산 거래 수 | C6: =COUNTIF(거래장부_스윙트레이딩!$L$6:$L$505,"청산") -> 2 | E6: 평균 수익 | F6: =IFERROR(AVERAGEIF(거래장부_스윙트레이딩!$P$6:$P$505,">0"),0) -> 190336 | H6: 최대 수익 거래 | I6: =IFERROR(MAX(거래장부_스윙트레이딩!$P$6:$P$505),0) -> 190336
B7: 보유중 거래 수 | C7: =COUNTIF(거래장부_스윙트레이딩!$L$6:$L$505,"보유중") -> 1 | E7: 평균 손실 | F7: =IFERROR(AVERAGEIF(거래장부_스윙트레이딩!$P$6:$P$505,"<0"),0) -> -99425 | H7: └ 종목 | I7: =IFERROR(INDEX(거래장부_스윙트레이딩!$C$6:$C$505,MATCH(MAX(거래장부_스윙트레이딩!$P$6:$P$505),거래장부_스윙트레이딩!$P$6:$P$505,0)),"-") -> 삼성전자
B8: 수익 거래 수 | C8: =COUNTIF(거래장부_스윙트레이딩!$P$6:$P$505,">0") -> 1 | E8: 평균 손익비 (R/R) | F8: =IFERROR($F$6/ABS($F$7),0) -> 1.9143676 | H8: 최대 손실 거래 | I8: =IFERROR(MIN(거래장부_스윙트레이딩!$P$6:$P$505),0) -> -99425
B9: 손실 거래 수 | C9: =COUNTIF(거래장부_스윙트레이딩!$P$6:$P$505,"<0") -> 1 | E9: 전체 평균 수익률 | F9: =IFERROR(AVERAGE(거래장부_스윙트레이딩!$Q$6:$Q$505),0) -> 0.017748364 | H9: └ 종목 | I9: =IFERROR(INDEX(거래장부_스윙트레이딩!$C$6:$C$505,MATCH(MIN(거래장부_스윙트레이딩!$P$6:$P$505),거래장부_스윙트레이딩!$P$6:$P$505,0)),"-") -> NAVER
B10: 승률 | C10: =IFERROR($C$8/$C$6,0) -> 0.5 | E10: 수익 거래 평균 수익률 | F10: =IFERROR(AVERAGEIFS(거래장부_스윙트레이딩!$Q$6:$Q$505,거래장부_스윙트레이딩!$P$6:$P$505,">0"),0) -> 0.093301961 | H10: 최고 수익률 | I10: =IFERROR(MAX(거래장부_스윙트레이딩!$Q$6:$Q$505),0) -> 0.093301961
B11: 총 실현손익 | C11: =SUM(거래장부_스윙트레이딩!$P$6:$P$505) -> 90911 | E11: 손실 거래 평균 수익률 | F11: =IFERROR(AVERAGEIFS(거래장부_스윙트레이딩!$Q$6:$Q$505,거래장부_스윙트레이딩!$P$6:$P$505,"<0"),0) -> -0.057805233 | H11: 최저 수익률 | I11: =IFERROR(MIN(거래장부_스윙트레이딩!$Q$6:$Q$505),0) -> -0.057805233
B12: 총 수익 합계 | C12: =SUMIF(거래장부_스윙트레이딩!$P$6:$P$505,">0") -> 190336 | E12: 평균 보유일수 | F12: =IFERROR(AVERAGEIFS(거래장부_스윙트레이딩!$R$6:$R$505,거래장부_스윙트레이딩!$L$6:$L$505,"청산"),0) -> 16 | H12: 최장 보유일수 (청산) | I12: =IFERROR(_xlfn.MAXIFS(거래장부_스윙트레이딩!$R$6:$R$505,거래장부_스윙트레이딩!$L$6:$L$505,"청산"),0) -> 25
B13: 총 손실 합계 | C13: =SUMIF(거래장부_스윙트레이딩!$P$6:$P$505,"<0") -> -99425 | E13: 수익 거래 평균 보유일수 | F13: =IFERROR(AVERAGEIFS(거래장부_스윙트레이딩!$R$6:$R$505,거래장부_스윙트레이딩!$P$6:$P$505,">0"),0) -> 25 | H13: 총 매수금액 (누적) | I13: =SUM(거래장부_스윙트레이딩!$M$6:$M$505) -> 5540000
B14: 손익비 (Profit Factor) | C14: =IFERROR($C$12/ABS($C$13),0) -> 1.9143676 | E14: 손실 거래 평균 보유일수 | F14: =IFERROR(AVERAGEIFS(거래장부_스윙트레이딩!$R$6:$R$505,거래장부_스윙트레이딩!$P$6:$P$505,"<0"),0) -> 7 | H14: 현재 보유중 투입원금 | I14: =SUMIF(거래장부_스윙트레이딩!$L$6:$L$505,"보유중",거래장부_스윙트레이딩!$M$6:$M$505) -> 1780000
B15: 기대값 (거래당) | C15: =IFERROR($C$11/$C$6,0) -> 45455.5 | E15: 최대 연속 수익 | F15: =IFERROR(MAX(거래장부_스윙트레이딩!$V$6:$V$505),0) -> 1 | H15: 초기자본 대비 수익률 | I15: =IFERROR($C$11/설정!$C$7,0) -> 0.02272775
B16: 총 거래비용 | C16: =SUM(거래장부_스윙트레이딩!$O$6:$O$505) -> 8356 | E16: 최대 연속 손실 | F16: =IFERROR(MAX(거래장부_스윙트레이딩!$W$6:$W$505),0) -> 1 | H16: 비용 / 총수익 비중 | I16: =IFERROR($C$16/$C$12,0) -> 0.043901311
B19: 월별 성과
B20: 월 | C20: 청산 건수 | D20: 실현손익 | E20: 누적 실현손익 | F20: 승률 | G20: 최대 수익 | H20: 최대 손실 | I20: 평균 수익률
B21: =DATE(YEAR(설정!$C$8),MONTH(설정!$C$8),1) -> 45931 | C21: =COUNTIFS(거래장부_스윙트레이딩!$S$6:$S$505,$B21) -> 0 | D21: =SUMIFS(거래장부_스윙트레이딩!$P$6:$P$505,거래장부_스윙트레이딩!$S$6:$S$505,$B21) -> 0 | E21: =SUM($D$21:$D21) -> 0 | F21: =IFERROR(COUNTIFS(거래장부_스윙트레이딩!$S$6:$S$505,$B21,거래장부_스윙트레이딩!$P$6:$P$505,">0")/$C21,"") | G21: =IFERROR(_xlfn.MAXIFS(거래장부_스윙트레이딩!$P$6:$P$505,거래장부_스윙트레이딩!$S$6:$S$505,$B21),0) -> 0 | H21: =IFERROR(_xlfn.MINIFS(거래장부_스윙트레이딩!$P$6:$P$505,거래장부_스윙트레이딩!$S$6:$S$505,$B21),0) -> 0 | I21: =IFERROR(AVERAGEIFS(거래장부_스윙트레이딩!$Q$6:$Q$505,거래장부_스윙트레이딩!$S$6:$S$505,$B21),"")
B22: =EDATE($B21,1) -> 45962 | C22: =COUNTIFS(거래장부_스윙트레이딩!$S$6:$S$505,$B22) -> 2 | D22: =SUMIFS(거래장부_스윙트레이딩!$P$6:$P$505,거래장부_스윙트레이딩!$S$6:$S$505,$B22) -> 90911 | E22: =SUM($D$21:$D22) -> 90911 | F22: =IFERROR(COUNTIFS(거래장부_스윙트레이딩!$S$6:$S$505,$B22,거래장부_스윙트레이딩!$P$6:$P$505,">0")/$C22,"") -> 0.5 | G22: =IFERROR(_xlfn.MAXIFS(거래장부_스윙트레이딩!$P$6:$P$505,거래장부_스윙트레이딩!$S$6:$S$505,$B22),0) -> 190336 | H22: =IFERROR(_xlfn.MINIFS(거래장부_스윙트레이딩!$P$6:$P$505,거래장부_스윙트레이딩!$S$6:$S$505,$B22),0) -> -99425 | I22: =IFERROR(AVERAGEIFS(거래장부_스윙트레이딩!$Q$6:$Q$505,거래장부_스윙트레이딩!$S$6:$S$505,$B22),"") -> 0.017748364
B23: =EDATE($B22,1) -> 45992 | C23: =COUNTIFS(거래장부_스윙트레이딩!$S$6:$S$505,$B23) -> 0 | D23: =SUMIFS(거래장부_스윙트레이딩!$P$6:$P$505,거래장부_스윙트레이딩!$S$6:$S$505,$B23) -> 0 | E23: =SUM($D$21:$D23) -> 90911 | F23: =IFERROR(COUNTIFS(거래장부_스윙트레이딩!$S$6:$S$505,$B23,거래장부_스윙트레이딩!$P$6:$P$505,">0")/$C23,"") | G23: =IFERROR(_xlfn.MAXIFS(거래장부_스윙트레이딩!$P$6:$P$505,거래장부_스윙트레이딩!$S$6:$S$505,$B23),0) -> 0 | H23: =IFERROR(_xlfn.MINIFS(거래장부_스윙트레이딩!$P$6:$P$505,거래장부_스윙트레이딩!$S$6:$S$505,$B23),0) -> 0 | I23: =IFERROR(AVERAGEIFS(거래장부_스윙트레이딩!$Q$6:$Q$505,거래장부_스윙트레이딩!$S$6:$S$505,$B23),"")
B24: =EDATE($B23,1) -> 46023 | C24: =COUNTIFS(거래장부_스윙트레이딩!$S$6:$S$505,$B24) -> 0 | D24: =SUMIFS(거래장부_스윙트레이딩!$P$6:$P$505,거래장부_스윙트레이딩!$S$6:$S$505,$B24) -> 0 | E24: =SUM($D$21:$D24) -> 90911 | F24: =IFERROR(COUNTIFS(거래장부_스윙트레이딩!$S$6:$S$505,$B24,거래장부_스윙트레이딩!$P$6:$P$505,">0")/$C24,"") | G24: =IFERROR(_xlfn.MAXIFS(거래장부_스윙트레이딩!$P$6:$P$505,거래장부_스윙트레이딩!$S$6:$S$505,$B24),0) -> 0 | H24: =IFERROR(_xlfn.MINIFS(거래장부_스윙트레이딩!$P$6:$P$505,거래장부_스윙트레이딩!$S$6:$S$505,$B24),0) -> 0 | I24: =IFERROR(AVERAGEIFS(거래장부_스윙트레이딩!$Q$6:$Q$505,거래장부_스윙트레이딩!$S$6:$S$505,$B24),"")
B25: =EDATE($B24,1) -> 46054 | C25: =COUNTIFS(거래장부_스윙트레이딩!$S$6:$S$505,$B25) -> 0 | D25: =SUMIFS(거래장부_스윙트레이딩!$P$6:$P$505,거래장부_스윙트레이딩!$S$6:$S$505,$B25) -> 0 | E25: =SUM($D$21:$D25) -> 90911 | F25: =IFERROR(COUNTIFS(거래장부_스윙트레이딩!$S$6:$S$505,$B25,거래장부_스윙트레이딩!$P$6:$P$505,">0")/$C25,"") | G25: =IFERROR(_xlfn.MAXIFS(거래장부_스윙트레이딩!$P$6:$P$505,거래장부_스윙트레이딩!$S$6:$S$505,$B25),0) -> 0 | H25: =IFERROR(_xlfn.MINIFS(거래장부_스윙트레이딩!$P$6:$P$505,거래장부_스윙트레이딩!$S$6:$S$505,$B25),0) -> 0 | I25: =IFERROR(AVERAGEIFS(거래장부_스윙트레이딩!$Q$6:$Q$505,거래장부_스윙트레이딩!$S$6:$S$505,$B25),"")
B26: =EDATE($B25,1) -> 46082 | C26: =COUNTIFS(거래장부_스윙트레이딩!$S$6:$S$505,$B26) -> 0 | D26: =SUMIFS(거래장부_스윙트레이딩!$P$6:$P$505,거래장부_스윙트레이딩!$S$6:$S$505,$B26) -> 0 | E26: =SUM($D$21:$D26) -> 90911 | F26: =IFERROR(COUNTIFS(거래장부_스윙트레이딩!$S$6:$S$505,$B26,거래장부_스윙트레이딩!$P$6:$P$505,">0")/$C26,"") | G26: =IFERROR(_xlfn.MAXIFS(거래장부_스윙트레이딩!$P$6:$P$505,거래장부_스윙트레이딩!$S$6:$S$505,$B26),0) -> 0 | H26: =IFERROR(_xlfn.MINIFS(거래장부_스윙트레이딩!$P$6:$P$505,거래장부_스윙트레이딩!$S$6:$S$505,$B26),0) -> 0 | I26: =IFERROR(AVERAGEIFS(거래장부_스윙트레이딩!$Q$6:$Q$505,거래장부_스윙트레이딩!$S$6:$S$505,$B26),"")
B27: =EDATE($B26,1) -> 46113 | C27: =COUNTIFS(거래장부_스윙트레이딩!$S$6:$S$505,$B27) -> 0 | D27: =SUMIFS(거래장부_스윙트레이딩!$P$6:$P$505,거래장부_스윙트레이딩!$S$6:$S$505,$B27) -> 0 | E27: =SUM($D$21:$D27) -> 90911 | F27: =IFERROR(COUNTIFS(거래장부_스윙트레이딩!$S$6:$S$505,$B27,거래장부_스윙트레이딩!$P$6:$P$505,">0")/$C27,"") | G27: =IFERROR(_xlfn.MAXIFS(거래장부_스윙트레이딩!$P$6:$P$505,거래장부_스윙트레이딩!$S$6:$S$505,$B27),0) -> 0 | H27: =IFERROR(_xlfn.MINIFS(거래장부_스윙트레이딩!$P$6:$P$505,거래장부_스윙트레이딩!$S$6:$S$505,$B27),0) -> 0 | I27: =IFERROR(AVERAGEIFS(거래장부_스윙트레이딩!$Q$6:$Q$505,거래장부_스윙트레이딩!$S$6:$S$505,$B27),"")
B28: =EDATE($B27,1) -> 46143 | C28: =COUNTIFS(거래장부_스윙트레이딩!$S$6:$S$505,$B28) -> 0 | D28: =SUMIFS(거래장부_스윙트레이딩!$P$6:$P$505,거래장부_스윙트레이딩!$S$6:$S$505,$B28) -> 0 | E28: =SUM($D$21:$D28) -> 90911 | F28: =IFERROR(COUNTIFS(거래장부_스윙트레이딩!$S$6:$S$505,$B28,거래장부_스윙트레이딩!$P$6:$P$505,">0")/$C28,"") | G28: =IFERROR(_xlfn.MAXIFS(거래장부_스윙트레이딩!$P$6:$P$505,거래장부_스윙트레이딩!$S$6:$S$505,$B28),0) -> 0 | H28: =IFERROR(_xlfn.MINIFS(거래장부_스윙트레이딩!$P$6:$P$505,거래장부_스윙트레이딩!$S$6:$S$505,$B28),0) -> 0 | I28: =IFERROR(AVERAGEIFS(거래장부_스윙트레이딩!$Q$6:$Q$505,거래장부_스윙트레이딩!$S$6:$S$505,$B28),"")
B29: =EDATE($B28,1) -> 46174 | C29: =COUNTIFS(거래장부_스윙트레이딩!$S$6:$S$505,$B29) -> 0 | D29: =SUMIFS(거래장부_스윙트레이딩!$P$6:$P$505,거래장부_스윙트레이딩!$S$6:$S$505,$B29) -> 0 | E29: =SUM($D$21:$D29) -> 90911 | F29: =IFERROR(COUNTIFS(거래장부_스윙트레이딩!$S$6:$S$505,$B29,거래장부_스윙트레이딩!$P$6:$P$505,">0")/$C29,"") | G29: =IFERROR(_xlfn.MAXIFS(거래장부_스윙트레이딩!$P$6:$P$505,거래장부_스윙트레이딩!$S$6:$S$505,$B29),0) -> 0 | H29: =IFERROR(_xlfn.MINIFS(거래장부_스윙트레이딩!$P$6:$P$505,거래장부_스윙트레이딩!$S$6:$S$505,$B29),0) -> 0 | I29: =IFERROR(AVERAGEIFS(거래장부_스윙트레이딩!$Q$6:$Q$505,거래장부_스윙트레이딩!$S$6:$S$505,$B29),"")
B30: =EDATE($B29,1) -> 46204 | C30: =COUNTIFS(거래장부_스윙트레이딩!$S$6:$S$505,$B30) -> 0 | D30: =SUMIFS(거래장부_스윙트레이딩!$P$6:$P$505,거래장부_스윙트레이딩!$S$6:$S$505,$B30) -> 0 | E30: =SUM($D$21:$D30) -> 90911 | F30: =IFERROR(COUNTIFS(거래장부_스윙트레이딩!$S$6:$S$505,$B30,거래장부_스윙트레이딩!$P$6:$P$505,">0")/$C30,"") | G30: =IFERROR(_xlfn.MAXIFS(거래장부_스윙트레이딩!$P$6:$P$505,거래장부_스윙트레이딩!$S$6:$S$505,$B30),0) -> 0 | H30: =IFERROR(_xlfn.MINIFS(거래장부_스윙트레이딩!$P$6:$P$505,거래장부_스윙트레이딩!$S$6:$S$505,$B30),0) -> 0 | I30: =IFERROR(AVERAGEIFS(거래장부_스윙트레이딩!$Q$6:$Q$505,거래장부_스윙트레이딩!$S$6:$S$505,$B30),"")
B31: =EDATE($B30,1) -> 46235 | C31: =COUNTIFS(거래장부_스윙트레이딩!$S$6:$S$505,$B31) -> 0 | D31: =SUMIFS(거래장부_스윙트레이딩!$P$6:$P$505,거래장부_스윙트레이딩!$S$6:$S$505,$B31) -> 0 | E31: =SUM($D$21:$D31) -> 90911 | F31: =IFERROR(COUNTIFS(거래장부_스윙트레이딩!$S$6:$S$505,$B31,거래장부_스윙트레이딩!$P$6:$P$505,">0")/$C31,"") | G31: =IFERROR(_xlfn.MAXIFS(거래장부_스윙트레이딩!$P$6:$P$505,거래장부_스윙트레이딩!$S$6:$S$505,$B31),0) -> 0 | H31: =IFERROR(_xlfn.MINIFS(거래장부_스윙트레이딩!$P$6:$P$505,거래장부_스윙트레이딩!$S$6:$S$505,$B31),0) -> 0 | I31: =IFERROR(AVERAGEIFS(거래장부_스윙트레이딩!$Q$6:$Q$505,거래장부_스윙트레이딩!$S$6:$S$505,$B31),"")
B32: =EDATE($B31,1) -> 46266 | C32: =COUNTIFS(거래장부_스윙트레이딩!$S$6:$S$505,$B32) -> 0 | D32: =SUMIFS(거래장부_스윙트레이딩!$P$6:$P$505,거래장부_스윙트레이딩!$S$6:$S$505,$B32) -> 0 | E32: =SUM($D$21:$D32) -> 90911 | F32: =IFERROR(COUNTIFS(거래장부_스윙트레이딩!$S$6:$S$505,$B32,거래장부_스윙트레이딩!$P$6:$P$505,">0")/$C32,"") | G32: =IFERROR(_xlfn.MAXIFS(거래장부_스윙트레이딩!$P$6:$P$505,거래장부_스윙트레이딩!$S$6:$S$505,$B32),0) -> 0 | H32: =IFERROR(_xlfn.MINIFS(거래장부_스윙트레이딩!$P$6:$P$505,거래장부_스윙트레이딩!$S$6:$S$505,$B32),0) -> 0 | I32: =IFERROR(AVERAGEIFS(거래장부_스윙트레이딩!$Q$6:$Q$505,거래장부_스윙트레이딩!$S$6:$S$505,$B32),"")
B33: =EDATE($B32,1) -> 46296 | C33: =COUNTIFS(거래장부_스윙트레이딩!$S$6:$S$505,$B33) -> 0 | D33: =SUMIFS(거래장부_스윙트레이딩!$P$6:$P$505,거래장부_스윙트레이딩!$S$6:$S$505,$B33) -> 0 | E33: =SUM($D$21:$D33) -> 90911 | F33: =IFERROR(COUNTIFS(거래장부_스윙트레이딩!$S$6:$S$505,$B33,거래장부_스윙트레이딩!$P$6:$P$505,">0")/$C33,"") | G33: =IFERROR(_xlfn.MAXIFS(거래장부_스윙트레이딩!$P$6:$P$505,거래장부_스윙트레이딩!$S$6:$S$505,$B33),0) -> 0 | H33: =IFERROR(_xlfn.MINIFS(거래장부_스윙트레이딩!$P$6:$P$505,거래장부_스윙트레이딩!$S$6:$S$505,$B33),0) -> 0 | I33: =IFERROR(AVERAGEIFS(거래장부_스윙트레이딩!$Q$6:$Q$505,거래장부_스윙트레이딩!$S$6:$S$505,$B33),"")
... B44: =EDATE($B43,1) -> 46631 | C44: =COUNTIFS(거래장부_스윙트레이딩!$S$6:$S$505,$B44) -> 0 | D44: =SUMIFS(거래장부_스윙트레이딩!$P$6:$P$505,거래장부_스윙트레이딩!$S$6:$S$505,$B44) -> 0 | E44: =SUM($D$21:$D44) -> 90911 | F44: =IFERROR(COUNTIFS(거래장부_스윙트레이딩!$S$6:$S$505,$B44,거래장부_스윙트레이딩!$P$6:$P$505,">0")/$C44,"") | G44: =IFERROR(_xlfn.MAXIFS(거래장부_스윙트레이딩!$P$6:$P$505,거래장부_스윙트레이딩!$S$6:$S$505,$B44),0) -> 0 | H44: =IFERROR(_xlfn.MINIFS(거래장부_스윙트레이딩!$P$6:$P$505,거래장부_스윙트레이딩!$S$6:$S$505,$B44),0) -> 0 | I44: =IFERROR(AVERAGEIFS(거래장부_스윙트레이딩!$Q$6:$Q$505,거래장부_스윙트레이딩!$S$6:$S$505,$B44),"")
B45: 합계 | C45: =SUM($C$21:$C$44) -> 2 | D45: =SUM($D$21:$D$44) -> 90911 | E45: =$E$44 -> 90911 | G45: =IFERROR(MAX($G$21:$G$44),0) -> 190336 | H45: =IFERROR(MIN($H$21:$H$44),0) -> -99425
B47: 수익 TOP 5
B48: 순위 | C48: 종목명 | D48: 매수일자 | E48: 매도일자 | F48: 순손익 | G48: 수익률 | H48: 보유일수
B49: 1 | C49: =IF($F49="","-",IFERROR(INDEX(거래장부_스윙트레이딩!$C$6:$C$505,MATCH($F49,거래장부_스윙트레이딩!$P$6:$P$505,0)),"-")) -> 삼성전자 | D49: =IF($F49="","",IFERROR(INDEX(거래장부_스윙트레이딩!$D$6:$D$505,MATCH($F49,거래장부_스윙트레이딩!$P$6:$P$505,0)),"")) -> 45950 | E49: =IF($F49="","",IFERROR(INDEX(거래장부_스윙트레이딩!$H$6:$H$505,MATCH($F49,거래장부_스윙트레이딩!$P$6:$P$505,0)),"")) -> 45975 | F49: =IFERROR(IF(LARGE(거래장부_스윙트레이딩!$P$6:$P$505,$B49)>0,LARGE(거래장부_스윙트레이딩!$P$6:$P$505,$B49),""),"") -> 190336 | G49: =IF($F49="","",IFERROR(INDEX(거래장부_스윙트레이딩!$Q$6:$Q$505,MATCH($F49,거래장부_스윙트레이딩!$P$6:$P$505,0)),"")) -> 0.093301961 | H49: =IF($F49="","",IFERROR(INDEX(거래장부_스윙트레이딩!$R$6:$R$505,MATCH($F49,거래장부_스윙트레이딩!$P$6:$P$505,0)),"")) -> 25
B50: 2 | C50: =IF($F50="","-",IFERROR(INDEX(거래장부_스윙트레이딩!$C$6:$C$505,MATCH($F50,거래장부_스윙트레이딩!$P$6:$P$505,0)),"-")) -> - | D50: =IF($F50="","",IFERROR(INDEX(거래장부_스윙트레이딩!$D$6:$D$505,MATCH($F50,거래장부_스윙트레이딩!$P$6:$P$505,0)),"")) | E50: =IF($F50="","",IFERROR(INDEX(거래장부_스윙트레이딩!$H$6:$H$505,MATCH($F50,거래장부_스윙트레이딩!$P$6:$P$505,0)),"")) | F50: =IFERROR(IF(LARGE(거래장부_스윙트레이딩!$P$6:$P$505,$B50)>0,LARGE(거래장부_스윙트레이딩!$P$6:$P$505,$B50),""),"") | G50: =IF($F50="","",IFERROR(INDEX(거래장부_스윙트레이딩!$Q$6:$Q$505,MATCH($F50,거래장부_스윙트레이딩!$P$6:$P$505,0)),"")) | H50: =IF($F50="","",IFERROR(INDEX(거래장부_스윙트레이딩!$R$6:$R$505,MATCH($F50,거래장부_스윙트레이딩!$P$6:$P$505,0)),""))
B51: 3 | C51: =IF($F51="","-",IFERROR(INDEX(거래장부_스윙트레이딩!$C$6:$C$505,MATCH($F51,거래장부_스윙트레이딩!$P$6:$P$505,0)),"-")) -> - | D51: =IF($F51="","",IFERROR(INDEX(거래장부_스윙트레이딩!$D$6:$D$505,MATCH($F51,거래장부_스윙트레이딩!$P$6:$P$505,0)),"")) | E51: =IF($F51="","",IFERROR(INDEX(거래장부_스윙트레이딩!$H$6:$H$505,MATCH($F51,거래장부_스윙트레이딩!$P$6:$P$505,0)),"")) | F51: =IFERROR(IF(LARGE(거래장부_스윙트레이딩!$P$6:$P$505,$B51)>0,LARGE(거래장부_스윙트레이딩!$P$6:$P$505,$B51),""),"") | G51: =IF($F51="","",IFERROR(INDEX(거래장부_스윙트레이딩!$Q$6:$Q$505,MATCH($F51,거래장부_스윙트레이딩!$P$6:$P$505,0)),"")) | H51: =IF($F51="","",IFERROR(INDEX(거래장부_스윙트레이딩!$R$6:$R$505,MATCH($F51,거래장부_스윙트레이딩!$P$6:$P$505,0)),""))
B52: 4 | C52: =IF($F52="","-",IFERROR(INDEX(거래장부_스윙트레이딩!$C$6:$C$505,MATCH($F52,거래장부_스윙트레이딩!$P$6:$P$505,0)),"-")) -> - | D52: =IF($F52="","",IFERROR(INDEX(거래장부_스윙트레이딩!$D$6:$D$505,MATCH($F52,거래장부_스윙트레이딩!$P$6:$P$505,0)),"")) | E52: =IF($F52="","",IFERROR(INDEX(거래장부_스윙트레이딩!$H$6:$H$505,MATCH($F52,거래장부_스윙트레이딩!$P$6:$P$505,0)),"")) | F52: =IFERROR(IF(LARGE(거래장부_스윙트레이딩!$P$6:$P$505,$B52)>0,LARGE(거래장부_스윙트레이딩!$P$6:$P$505,$B52),""),"") | G52: =IF($F52="","",IFERROR(INDEX(거래장부_스윙트레이딩!$Q$6:$Q$505,MATCH($F52,거래장부_스윙트레이딩!$P$6:$P$505,0)),"")) | H52: =IF($F52="","",IFERROR(INDEX(거래장부_스윙트레이딩!$R$6:$R$505,MATCH($F52,거래장부_스윙트레이딩!$P$6:$P$505,0)),""))
B53: 5 | C53: =IF($F53="","-",IFERROR(INDEX(거래장부_스윙트레이딩!$C$6:$C$505,MATCH($F53,거래장부_스윙트레이딩!$P$6:$P$505,0)),"-")) -> - | D53: =IF($F53="","",IFERROR(INDEX(거래장부_스윙트레이딩!$D$6:$D$505,MATCH($F53,거래장부_스윙트레이딩!$P$6:$P$505,0)),"")) | E53: =IF($F53="","",IFERROR(INDEX(거래장부_스윙트레이딩!$H$6:$H$505,MATCH($F53,거래장부_스윙트레이딩!$P$6:$P$505,0)),"")) | F53: =IFERROR(IF(LARGE(거래장부_스윙트레이딩!$P$6:$P$505,$B53)>0,LARGE(거래장부_스윙트레이딩!$P$6:$P$505,$B53),""),"") | G53: =IF($F53="","",IFERROR(INDEX(거래장부_스윙트레이딩!$Q$6:$Q$505,MATCH($F53,거래장부_스윙트레이딩!$P$6:$P$505,0)),"")) | H53: =IF($F53="","",IFERROR(INDEX(거래장부_스윙트레이딩!$R$6:$R$505,MATCH($F53,거래장부_스윙트레이딩!$P$6:$P$505,0)),""))
B55: 손실 TOP 5
B56: 순위 | C56: 종목명 | D56: 매수일자 | E56: 매도일자 | F56: 순손익 | G56: 수익률 | H56: 보유일수
...

Sheet 원본거래내역
A1: 증권사 거래내역 원본 (보관용)
A2: HTS/MTS에서 내려받은 거래내역을 3행부터 그대로 붙여넣는다. 한 거래가 두 줄(윗줄/아랫줄)로 구성된 증권사 양식 그대로 보관하는 시트이며, 손익 계산에는 사용되지 않는다. 매매 손익은 거래장부 시트에 정리해서 입력할 것.
A3: 거래일자 | B3: 거래번호 | C3: 거래적요 | D3: 종목코드 | E3: 수량 | F3: 수수료 | G3: 세전이자 | H3: 거래금액 | I3: 미수발생/변제금 | J3: 질권자 | K3: 예수금잔고 | L3: 거래원금 | M3: 매수일자(질권설정일/출고일) | N3: 경과일수 | O3: 통화구분
A4: 처리지점 | B4: 거래원번 | C4: 관련계좌 | D4: 종목명 | E4: 단가 | F4: 제세금 | G4: 신용이자 | H4: 반영금액 | I4: 융자/대주금액 | J4: 질권설정수량 | K4: 유가증권잔고 | L4: 원금잔액 | M4: 만기일자 | N4: 적용금리 | O4: 외화예수금잔고
A5: 2025-12-09 | B5: 1 | C5: 전자계좌입금 | F5: 0 | G5: 0 | H5: 2000000 | I5: 0 | K5: 2000000 | L5: 0 | N5: 0
A6: 디지털센터 | B6: 0 | C6: 하나은행/안현준 | F6: 0 | G6: 0 | H6: 2000000 | I6: 0 | K6: 0 | L6: 0 | N6: 0 | O6: 0
A7: 2025-10-17 | B7: 8 | C7: 전자계좌입금 | F7: 0 | G7: 0 | H7: 2000000 | I7: 0 | K7: 4000297 | L7: 0 | N7: 0
A8: 디지털센터 | B8: 0 | C8: 하나은행/안현준 | F8: 0 | G8: 0 | H8: 2000000 | I8: 0 | K8: 0 | L8: 0 | N8: 0 | O8: 0
A9: 2025-10-19 | B9: 10 | C9: 전자계좌입금 | F9: 0 | G9: 0 | H9: 1000000 | I9: 0 | K9: 1000000 | L9: 0 | N9: 0
A10: 디지털센터 | B10: 0 | C10: 하나은행/안현준 | F10: 0 | G10: 0 | H10: 1000000 | I10: 0 | K10: 0 | L10: 0 | N10: 0 | O10: 0
